try {
  console.log('hello')
  const t = 'v'
  throw t
} catch (e) {
  console.log('was an error thrown?')
  console.log()
}